Workbook

Sheet RD
A1: AMAZON.COM, INC. RAW FINANCIAL DATA | 2021–2025 | $ in Millions
B2: Source: Amazon 10-K / Annual Reports (2021–2025) | SEC EDGAR
B3: P&L
B4: Item | C4: 2021 | D4: 2022 | E4: 2023 | F4: 2024 | G4: 2025
B5: Revenue ($mm) | C5: 469822 | D5: 513983 | E5: 574785 | F5: 637959 | G5: 716924
B6: Cost of Revenue | C6: 272344 | D6: 288831 | E6: 304739 | F6: 326288 | G6: 356414
B7: Gross Profit | C7: 197478 | D7: 225152 | E7: 270046 | F7: 311671 | G7: 360510
B8: Gross Margin % | C8: 0.4203 | D8: 0.4381 | E8: 0.4698 | F8: 0.4885 | G8: 0.5029
B9: R&D Expenses | C9: 56052 | D9: 73213 | E9: 85622 | F9: 88544 | G9: 108521
B10: SG&A Expenses | C10: 116485 | D10: 138428 | E10: 146805 | F10: 153771 | G10: 167375
B11: Other OpEx | C11: 62 | D11: 163 | E11: 767 | F11: 763 | G11: 4639
B12: Total Operating Expenses | C12: 172599 | D12: 211804 | E12: 233194 | F12: 243078 | G12: 280535
B13: Operating Income (EBIT) | C13: 24879 | D13: 13348 | E13: 36852 | F13: 68593 | G13: 79975
B14: EBIT Margin % | C14: 0.053 | D14: 0.026 | E14: 0.0641 | F14: 0.1075 | G14: 0.1116
B15: Interest Expense | C15: -1809 | D15: -2367 | E15: -3182 | F15: -2406 | G15: -2274
B16: Interest Income | C16: 448 | D16: 989 | E16: 2949 | F16: 4677 | G16: 4381
... B24: Diluted Shares (mm) | C24: 10296 | D24: 10189 | E24: 10492 | F24: 10721 | G24: 10827
B26: Balance Sheet
B27: Item | C27: 2021 | D27: 2022 | E27: 2023 | F27: 2024 | G27: 2025
B28: Cash & Equivalents | C28: 36220 | D28: 53888 | E28: 73387 | F28: 78779 | G28: 86810
B29: Short-Term Investments | C29: 59829 | D29: 16138 | E29: 13393 | F29: 22423 | G29: 36219
B30: Accounts Receivable | C30: 25500 | D30: 36202 | E30: 42600 | F30: 45900 | G30: 56300
B31: Inventory | C31: 32640 | D31: 34405 | E31: 33318 | F31: 34214 | G31: 38325
B32: Total Current Assets | C32: 161580 | D32: 146791 | E32: 172351 | F32: 190867 | G32: 229083
B33: Net PP&E | C33: 216363 | D33: 252838 | E33: 276690 | F33: 328806 | G33: 443079
B34: Intangible Assets | C34: 20478 | D34: 26385 | E34: 30476 | F34: 31676 | G34: 32470
B35: Goodwill | C35: 15371 | D35: 20288 | E35: 22789 | F35: 23074 | G35: 23273
B36: Other Long-Term Assets | C36: 18125 | D36: 33846 | E36: 44769 | F36: 68656 | G36: 93851
B37: Total Assets | C37: 420549 | D37: 462675 | E37: 527854 | F37: 624894 | G37: 818042
B38: Accounts Payable | C38: 78664 | D38: 79600 | E38: 84981 | F38: 94363 | G38: 121909
B39: Short-Term Borrowings | C39: 1043 | D39: 8000 | E39: 147 | F39: 151 | G39: 455
... B47: Total Liabilities & Equity | C47: 420549 | D47: 462675 | E47: 527854 | F47: 624894 | G47: 818042
B49: Cash Flow
B50: Item | C50: 2021 | D50: 2022 | E50: 2023 | F50: 2024 | G50: 2025
B51: Cash from Operations | C51: 46327 | D51: 46752 | E51: 84946 | F51: 115877 | G51: 139514
B52: Net Income | C52: 33364 | D52: -2722 | E52: 30425 | F52: 59248 | G52: 77670
B53: D&A | C53: 34433 | D53: 41921 | E53: 48663 | F53: 52795 | G53: 65756
B54: Change in Working Capital | C54: -19611 | D54: -20886 | E54: -11541 | F54: -15541 | G54: -19969
B55: Cash from Investing | C55: -58154 | D55: -37601 | E55: -49833 | F55: -94342 | G55: -142545
B56: Capital Expenditures | C56: -61053 | D56: -63645 | E56: -52729 | F56: -82999 | G56: -131819
...

Sheet CD
A1: AMAZON.COM, INC. — CLEAN DATA SUMMARY | 2021–2025 | $ in Millions
B2: Normalized from Raw Data | Cross-referenced with SEC filings
B3: INCOME STATEMENT
B4: Line Item | C4: 2021 | D4: 2022 | E4: 2023 | F4: 2024 | G4: 2025
B5: Revenue ($mm) | C5: 469822 | D5: 513983 | E5: 574785 | F5: 637959 | G5: 716924
B6: Cost of Revenue | C6: 272344 | D6: 288831 | E6: 304739 | F6: 326288 | G6: 356414
B7: Gross Profit | C7: 197478 | D7: 225152 | E7: 270046 | F7: 311671 | G7: 360510
B8: Gross Margin % | C8: 0.4203 | D8: 0.4381 | E8: 0.4698 | F8: 0.4885 | G8: 0.5029
B9: Total Operating Expenses | C9: 172599 | D9: 211804 | E9: 233194 | F9: 243078 | G9: 280535
B10: Operating Income (EBIT) | C10: 24879 | D10: 13348 | E10: 36852 | F10: 68593 | G10: 79975
B11: EBIT Margin % | C11: 0.053 | D11: 0.026 | E11: 0.0641 | F11: 0.1075 | G11: 0.1116
B12: Interest Expense (net) | C12: -1361 | D12: -1378 | E12: -233 | F12: 2271 | G12: 2107
B13: EBT | C13: 23518 | D13: 11970 | E13: 36619 | F13: 70864 | G13: 82082
B14: Income Tax | C14: 4791 | D14: -3217 | E14: 7120 | F14: 9265 | G14: 19087
B15: Net Income | C15: 33364 | D15: -2722 | E15: 30425 | F15: 59248 | G15: 77670
B16: Net Margin % | C16: 0.071 | D16: -0.0053 | E16: 0.0529 | F16: 0.0929 | G16: 0.1083
... B18: EBITDA Margin % | C18: 0.1262 | D18: 0.1075 | E18: 0.1488 | F18: 0.1903 | G18: 0.2033
B20: BALANCE SHEET
B21: Line Item | C21: 2021 | D21: 2022 | E21: 2023 | F21: 2024 | G21: 2025
B22: Cash & Equivalents | C22: 36220 | D22: 53888 | E22: 73387 | F22: 78779 | G22: 86810
B23: Accounts Receivable | C23: 25500 | D23: 36202 | E23: 42600 | F23: 45900 | G23: 56300
B24: Inventory | C24: 32640 | D24: 34405 | E24: 33318 | F24: 34214 | G24: 38325
B25: Net PP&E | C25: 216363 | D25: 252838 | E25: 276690 | F25: 328806 | G25: 443079
B26: Total Assets | C26: 420549 | D26: 462675 | E26: 527854 | F26: 624894 | G26: 818042
B27: Accounts Payable | C27: 78664 | D27: 79600 | E27: 84981 | F27: 94363 | G27: 121909
B28: Short-Term Borrowings | C28: 1043 | D28: 8000 | E28: 147 | F28: 151 | G28: 455
B29: Long-Term Debt | C29: 54944 | D29: 73850 | E29: 64914 | F29: 59723 | G29: 73448
B30: Total Liabilities | C30: 282304 | D30: 316632 | E30: 325979 | F30: 338924 | G30: 406977
B31: Retained Earnings | C31: 85915 | D31: 83193 | E31: 113618 | F31: 172866 | G31: 250536
B32: Total Equity | C32: 138245 | D32: 146043 | E32: 201875 | F32: 285970 | G32: 411065
B33: Total Liabilities & Equity | C33: 420549 | D33: 462675 | E33: 527854 | F33: 624894 | G33: 818042
B35: CASH FLOW
B36: Line Item | C36: 2021 | D36: 2022 | E36: 2023 | F36: 2024 | G36: 2025
B37: Cash from Operations | C37: 46327 | D37: 46752 | E37: 84946 | F37: 115877 | G37: 139514
B38: Net Income | C38: 33364 | D38: -2722 | E38: 30425 | F38: 59248 | G38: 77670
B39: D&A | C39: 34433 | D39: 41921 | E39: 48663 | F39: 52795 | G39: 65756
B40: Change in Working Capital | C40: -19611 | D40: -20886 | E40: -11541 | F40: -15541 | G40: -19969
B41: Cash from Investing | C41: -58154 | D41: -37601 | E41: -49833 | F41: -94342 | G41: -142545
B42: CapEx | C42: -61053 | D42: -63645 | E42: -52729 | F42: -82999 | G42: -131819
B43: Cash from Financing | C43: 6291 | D43: 9718 | E43: -15879 | F43: -11812 | G43: 9661
...

Sheet Assumptions
A1: AMAZON — MODEL ASSUMPTIONS | Forecast: 2026F–2027F
B3: INCOME STATEMENT DRIVERS
B4: Revenue Growth % (2026F) | C4: 0.12 | D4: Avg of last 3yr CAGR; Amazon guided high-single-digit growth
B5: Revenue Growth % (2027F) | C5: 0.13 | D5: Slight acceleration from AWS + Advertising
B6: Cost of Revenue % of Rev | C6: 0.497 | D6: 5yr avg declining trend; 2025 actual = 49.7%
B7: Operating Expense % of Rev | C7: 0.392 | D7: 5yr avg; includes R&D + SG&A
B8: Tax Rate % | C8: 0.21 | D8: US federal statutory rate; Amazon effective ~21-24%
B10: BALANCE SHEET DRIVERS
B11: AR Days (Days Sales Out.) | C11: 28 | D11: AR/Revenue*365; Amazon ~28 days historically
B12: Inventory % of Revenue | C12: 0.054 | D12: Inventory/Revenue; ~5.4% (2025 actual)
B13: AP Days (Days Payable Out.) | C13: 62 | D13: AP/Revenue*365; Amazon ~62 days historically
B14: CapEx % of Revenue | C14: 0.17 | D14: Stepped up in 2025 to 18.4%; moderating to 17%
B15: D&A % of Net PP&E | C15: 0.148 | D15: D&A/Net PP&E; Amazon 2025 ~14.8%
B17: DEBT & FINANCING
B18: Interest Rate on LT Debt | C18: 0.033 | D18: Blended coupon on Amazon's outstanding debt ~3.3%
B19: LT Debt Growth % | C19: 0.05 | D19: Modest debt growth; Amazon has strong FCF coverage

Sheet IS
A1: AMAZON.COM, INC. — INCOME STATEMENT | $ in Millions
B2: Historical: 2021–2025 (Actual) | Forecast: 2026F–2027F (Model-Driven)
B3: $ in Millions | C3: 2021 | D3: 2022 | E3: 2023 | F3: 2024 | G3: 2025 | H3: 2026F | I3: 2027F
B4: Revenue ($mm) | C4: 469822 | D4: 513983 | E4: 574785 | F4: 637959 | G4: 716924 | H4: =G4*(1+Assumptions!C4) -> 802954.88 | I4: =H4*(1+Assumptions!C5) -> 907339.01
B5: Cost of Revenue | C5: 272344 | D5: 288831 | E5: 304739 | F5: 326288 | G5: 356414 | H5: =H4*Assumptions!C6 -> 399068.58 | I5: =I4*Assumptions!C6 -> 450947.49
B6: Gross Profit | C6: 197478 | D6: 225152 | E6: 270046 | F6: 311671 | G6: 360510 | H6: =H4-H5 -> 403886.3 | I6: =I4-I5 -> 456391.52
B7: Gross Margin % | C7: 0.4203 | D7: 0.4381 | E7: 0.4698 | F7: 0.4885 | G7: 0.5029 | H7: =H6/H4 -> 0.503 | I7: =I6/I4 -> 0.503
B8: Operating Expenses | C8: 172599 | D8: 211804 | E8: 233194 | F8: 243078 | G8: 280535 | H8: =H4*Assumptions!C7 -> 314758.31 | I8: =I4*Assumptions!C7 -> 355676.89
B9: Operating Income (EBIT) | C9: 24879 | D9: 13348 | E9: 36852 | F9: 68593 | G9: 79975 | H9: =H6-H8 -> 89127.992 | I9: =I6-I8 -> 100714.63
B10: EBIT Margin % | C10: 0.053 | D10: 0.026 | E10: 0.0641 | F10: 0.1075 | G10: 0.1116 | H10: =H9/H4 -> 0.111 | I10: =I9/I4 -> 0.111
B11: Interest Expense | C11: 1809 | D11: 2367 | E11: 3182 | F11: 2406 | G11: 2274 | H11: =BS!H14*Assumptions!C18 -> 2544.9732 | I11: =BS!I14*Assumptions!C18 -> 2672.2219
B12: EBT (Earnings Before Tax) | C12: 23518 | D12: 11970 | E12: 36619 | F12: 70864 | G12: 82082 | H12: =H9-H11 -> 86583.018 | I12: =I9-I11 -> 98042.409
B13: Income Tax Expense | C13: 4791 | D13: -3217 | E13: 7120 | F13: 9265 | G13: 19087 | H13: =MAX(0,H12*Assumptions!C8) -> 18182.434 | I13: =MAX(0,I12*Assumptions!C8) -> 20588.906
B14: Net Income | C14: 33364 | D14: -2722 | E14: 30425 | F14: 59248 | G14: 77670 | H14: =H12-H13 -> 68400.585 | I14: =I12-I13 -> 77453.503
B15: Net Margin % | C15: 0.071 | D15: -0.0053 | E15: 0.0529 | F15: 0.0929 | G15: 0.1083 | H15: =H14/H4 -> 0.085186087 | I15: =I14/I4 -> 0.085363356
B17: EBITDA | C17: 59312 | D17: 55269 | E17: 85515 | F17: 121388 | G17: 145731 | H17: =H9+H19 -> 154703.68 | I17: =I9+I19 -> 176787.46
B18: EBITDA Margin % | C18: 0.1262 | D18: 0.1075 | E18: 0.1488 | F18: 0.1903 | G18: 0.2033 | H18: =H17/H4 -> 0.19266797 | I18: =I17/I4 -> 0.19484169
B19: D&A (from CF) | C19: 34433 | D19: 41921 | E19: 48663 | F19: 52795 | G19: 65756 | H19: =CF!H6 -> 65575.692 | I19: =CF!I6 -> 76072.834
B21: Diluted Shares (mm) | C21: 10296 | D21: 10189 | E21: 10492 | F21: 10721 | G21: 10827 | H21: =G21*1.015 -> 10989.405 | I21: =H21*1.015 -> 11154.246
B22: Diluted EPS ($) | C22: 3.24 | D22: -0.27 | E22: 2.9 | F22: 5.53 | G22: 7.17 | H22: =H14/H21 -> 6.22423 | I22: =I14/I21 -> 6.9438582

Sheet BS
A1: AMAZON.COM, INC. — BALANCE SHEET | $ in Millions
B2: Historical: 2021–2025 (Actual) | Forecast: 2026F–2027F (Model-Driven)
B3: $ in Millions | C3: 2021 | D3: 2022 | E3: 2023 | F3: 2024 | G3: 2025 | H3: 2026F | I3: 2027F
B4: ASSETS
B5: Cash & Equivalents | C5: 36220 | D5: 53888 | E5: 73387 | F5: 78779 | G5: 86810 | H5: =G5+CF!H18 -> 86953.581 | I5: =H5+CF!I18 -> 89175.016
B6: Accounts Receivable | C6: 25500 | D6: 36202 | E6: 42600 | F6: 45900 | G6: 56300 | H6: =IS!H4*Assumptions!C11/365 -> 61596.539 | I6: =IS!I4*Assumptions!C11/365 -> 69604.089
B7: Inventory | C7: 32640 | D7: 34405 | E7: 33318 | F7: 34214 | G7: 38325 | H7: =IS!H4*Assumptions!C12 -> 43359.564 | I7: =IS!I4*Assumptions!C12 -> 48996.307
B8: Net PP&E | C8: 216363 | D8: 252838 | E8: 276690 | F8: 328806 | G8: 443079 | H8: =G8+(-CF!H10)-CF!H6 -> 514005.64 | I8: =H8+(-CF!I10)-CF!I6 -> 592180.44
B9: Other Assets (net) | C9: 109966 | D9: 119342 | E9: 133859 | F9: 167195 | G9: 213528 | H9: =H16+H20-H5-H6-H7-H8 -> 229434.8 | I9: =I16+I20-I5-I6-I7-I8 -> 260450.26
B10: Total Assets | C10: 420549 | D10: 462675 | E10: 527854 | F10: 624894 | G10: 818042 | H10: =H5+H6+H7+H8+H9 -> 935350.12 | I10: =I5+I6+I7+I8+I9 -> 1060406.1
B11: LIABILITIES & EQUITY
B12: Accounts Payable | C12: 78664 | D12: 79600 | E12: 84981 | F12: 94363 | G12: 121909 | H12: =IS!H4*Assumptions!C13/365 -> 136392.34 | I12: =IS!I4*Assumptions!C13/365 -> 154123.34
B13: Short-Term Borrowings | C13: 1043 | D13: 8000 | E13: 147 | F13: 151 | G13: 455 | H13: 300 | I13: 300
B14: Long-Term Debt | C14: 54944 | D14: 73850 | E14: 64914 | F14: 59723 | G14: 73448 | H14: =G14*(1+Assumptions!C19) -> 77120.4 | I14: =H14*(1+Assumptions!C19) -> 80976.42
B15: Other Liabilities | C15: 147653 | D15: 155182 | E15: 176937 | F15: 184687 | G15: 211165 | H15: =G15*1.08 -> 228058.2 | I15: =H15*1.06 -> 241741.69
B16: Total Liabilities | C16: 282304 | D16: 316632 | E16: 325979 | F16: 338924 | G16: 406977 | H16: =H12+H13+H14+H15 -> 441870.94 | I16: =I12+I13+I14+I15 -> 477141.45
B17: Retained Earnings | C17: 85915 | D17: 83193 | E17: 113618 | F17: 172866 | G17: 250536 | H17: =G17+IS!H14 -> 318936.58 | I17: =H17+IS!I14 -> 396390.09
B18: Common Stock & APIC | C18: 55543 | D18: 75174 | E18: 99134 | F18: 120975 | G18: 140136 | H18: =G18*1.1 -> 154149.6 | I18: =H18*1.08 -> 166481.57
B19: Other Equity | C19: -3213 | D19: -12324 | E19: -10877 | F19: -7871 | G19: 20393 | H19: =G19 -> 20393 | I19: =H19 -> 20393
B20: Total Equity | C20: 138245 | D20: 146043 | E20: 201875 | F20: 285970 | G20: 411065 | H20: =H17+H18+H19 -> 493479.18 | I20: =I17+I18+I19 -> 583264.66
B21: Total Liabilities & Equity | C21: 420549 | D21: 462675 | E21: 527854 | F21: 624894 | G21: 818042 | H21: =H16+H20 -> 935350.12 | I21: =I16+I20 -> 1060406.1
B23: BS CHECK (Assets = L+E): | H23: =IF(ROUND(H10,0)=ROUND(H21,0),"✔ BALANCED","✘ CHECK") -> ✔ BALANCED | I23: =IF(ROUND(I10,0)=ROUND(I21,0),"✔ BALANCED","✘ CHECK") -> ✔ BALANCED

Sheet CF
A1: AMAZON.COM, INC. — CASH FLOW STATEMENT | $ in Millions
B2: Historical: 2021–2025 (Actual) | Forecast: 2026F–2027F (Model-Driven)
B3: $ in Millions | C3: 2021 | D3: 2022 | E3: 2023 | F3: 2024 | G3: 2025 | H3: 2026F | I3: 2027F
B4: OPERATING ACTIVITIES
B5: Net Income | C5: 33364 | D5: -2722 | E5: 30425 | F5: 59248 | G5: 77670 | H5: =IS!H14 -> 68400.585 | I5: =IS!I14 -> 77453.503
B6: Depreciation & Amortization | C6: 34433 | D6: 41921 | E6: 48663 | F6: 52795 | G6: 65756 | H6: =Assumptions!C15*BS!G8 -> 65575.692 | I6: =Assumptions!C15*BS!H8 -> 76072.834
B7: Change in Working Capital | C7: -19611 | D7: -20886 | E7: -11541 | F7: -15541 | G7: -19969 | H7: =-((BS!H6-BS!G6)+(BS!H7-BS!G7)-(BS!H12-BS!G12)) -> 4152.2335 | I7: =-((BS!I6-BS!H6)+(BS!I7-BS!H7)-(BS!I12-BS!H12)) -> 4086.7104
B8: Cash from Operations | C8: 46327 | D8: 46752 | E8: 84946 | F8: 115877 | G8: 139514 | H8: =H5+H6+H7 -> 138128.51 | I8: =I5+I6+I7 -> 157613.05
B9: INVESTING ACTIVITIES
B10: Capital Expenditures (CapEx) | C10: -61053 | D10: -63645 | E10: -52729 | F10: -82999 | G10: -131819 | H10: =-Assumptions!C14*IS!H4 -> -136502.33 | I10: =-Assumptions!C14*IS!I4 -> -154247.63
B11: Other Investing Activities | C11: 2899 | D11: 26044 | E11: 2896 | F11: -11343 | G11: -10726 | H11: -5000 | I11: -5000
B12: Cash from Investing | C12: -58154 | D12: -37601 | E12: -49833 | F12: -94342 | G12: -142545 | H12: =H10+H11 -> -141502.33 | I12: =I10+I11 -> -159247.63
B13: FINANCING ACTIVITIES
B14: Net Debt Issued / (Repaid) | C14: 6259 | D14: 15718 | E14: -16879 | F14: -11811 | G14: 9661 | H14: =(BS!H14-BS!G14)+(BS!H13-BS!G13) -> 3517.4 | I14: =(BS!I14-BS!H14)+(BS!I13-BS!H13) -> 3856.02
B15: Other Financing | C15: 32 | D15: -6000 | E15: 1000 | F15: -1 | G15: 0 | H15: 0 | I15: 0
B16: Cash from Financing | C16: 6291 | D16: 9718 | E16: -15879 | F16: -11812 | G16: 9661 | H16: =H14+H15 -> 3517.4 | I16: =I14+I15 -> 3856.02
B17: NET CHANGE IN CASH
B18: Net Change in Cash | C18: -5900 | D18: 17776 | E18: 19637 | F18: 8422 | G18: 7794 | H18: =H8+H12+H16 -> 143.58052 | I18: =I8+I12+I16 -> 2221.4352
B19: Beginning Cash Balance | C19: 42120 | D19: 36220 | E19: 53888 | F19: 73387 | G19: 78779 | H19: =BS!G5 -> 86810 | I19: =BS!H5 -> 86953.581
B20: Ending Cash Balance | C20: 36220 | D20: 53888 | E20: 73387 | F20: 78779 | G20: 86810 | H20: =H18+H19 -> 86953.581 | I20: =I18+I19 -> 89175.016
B22: Free Cash Flow (CFO + CapEx) | C22: -14726 | D22: -16893 | E22: 32217 | F22: 32878 | G22: 7695 | H22: =H8+H10 -> 1626.1805 | I22: =I8+I10 -> 3365.4152
B23: FCF Margin % | H23: =H22/IS!H4 -> 0.0020252452 | I23: =I22/IS!I4 -> 0.0037091045

Sheet Model
A1: AMAZON.COM, INC. — 3-STATEMENT MODEL | SUMMARY DASHBOARD
B2: Built by: Kiruba Manimaran | Data: Amazon 10-K 2021–2025 | Forecast Period: 2026F–2027F | All figures in USD Millions
B3: Key Metrics ($mm) | C3: 2021 | D3: 2022 | E3: 2023 | F3: 2024 | G3: 2025 | H3: 2026F | I3: 2027F
B4: ── INCOME STATEMENT ──
B5: Revenue | C5: 469822 | D5: 513983 | E5: 574785 | F5: 637959 | G5: 716924 | H5: =IS!H4 -> 802954.88 | I5: =IS!I4 -> 907339.01
B6: Revenue Growth % | C6: 0.217 | D6: 0.094 | E6: 0.1183 | F6: 0.1099 | G6: 0.1238 | H6: =IS!H4/IS!G4-1 -> 0.12 | I6: =IS!I4/IS!H4-1 -> 0.13
B7: Gross Profit | C7: 197478 | D7: 225152 | E7: 270046 | F7: 311671 | G7: 360510 | H7: =IS!H6 -> 403886.3 | I7: =IS!I6 -> 456391.52
B8: Gross Margin % | C8: 0.4203 | D8: 0.4381 | E8: 0.4698 | F8: 0.4885 | G8: 0.5029 | H8: =IS!H6/IS!H4 -> 0.503 | I8: =IS!I6/IS!I4 -> 0.503
B9: EBIT | C9: 24879 | D9: 13348 | E9: 36852 | F9: 68593 | G9: 79975 | H9: =IS!H9 -> 89127.992 | I9: =IS!I9 -> 100714.63
B10: EBIT Margin % | C10: 0.053 | D10: 0.026 | E10: 0.0641 | F10: 0.1075 | G10: 0.1116 | H10: =IS!H9/IS!H4 -> 0.111 | I10: =IS!I9/IS!I4 -> 0.111
B11: EBITDA | C11: 59312 | D11: 55269 | E11: 85515 | F11: 121388 | G11: 145731 | H11: =IS!H17 -> 154703.68 | I11: =IS!I17 -> 176787.46
B12: EBITDA Margin % | C12: 0.1262 | D12: 0.1075 | E12: 0.1488 | F12: 0.1903 | G12: 0.2033 | H12: =IS!H17/IS!H4 -> 0.19266797 | I12: =IS!I17/IS!I4 -> 0.19484169
B13: Net Income | C13: 33364 | D13: -2722 | E13: 30425 | F13: 59248 | G13: 77670 | H13: =IS!H14 -> 68400.585 | I13: =IS!I14 -> 77453.503
B14: Net Margin % | C14: 0.071 | D14: -0.0053 | E14: 0.0529 | F14: 0.0929 | G14: 0.1083 | H14: =IS!H14/IS!H4 -> 0.085186087 | I14: =IS!I14/IS!I4 -> 0.085363356
B15: Diluted EPS ($) | C15: 3.24 | D15: -0.27 | E15: 2.9 | F15: 5.53 | G15: 7.17 | H15: =IS!H22 -> 6.22423 | I15: =IS!I22 -> 6.9438582
B16: ── CASH FLOW ──
B17: Cash from Operations | C17: 46327 | D17: 46752 | E17: 84946 | F17: 115877 | G17: 139514 | H17: =CF!H8 -> 138128.51 | I17: =CF!I8 -> 157613.05
B18: Capital Expenditures | C18: -61053 | D18: -63645 | E18: -52729 | F18: -82999 | G18: -131819 | H18: =CF!H9 -> 0 | I18: =CF!I9 -> 0
B19: Free Cash Flow | C19: -14726 | D19: -16893 | E19: 32217 | F19: 32878 | G19: 7695 | H19: =CF!H20 -> 86953.581 | I19: =CF!I20 -> 89175.016
B20: FCF Margin % | C20: -0.031 | D20: -0.033 | E20: 0.056 | F20: 0.052 | G20: 0.011 | H20: =CF!H20/IS!H4 -> 0.10829199 | I20: =CF!I20/IS!I4 -> 0.098281915
B21: ── BALANCE SHEET ──
B22: Cash & Equivalents | C22: 36220 | D22: 53888 | E22: 73387 | F22: 78779 | G22: 86810 | H22: =BS!H4 -> 0 | I22: =BS!I4 -> 0
B23: Total Assets | C23: 420549 | D23: 462675 | E23: 527854 | F23: 624894 | G23: 818042 | H23: =BS!H10 -> 935350.12 | I23: =BS!I10 -> 1060406.1
B24: Long-Term Debt | C24: 54944 | D24: 73850 | E24: 64914 | F24: 59723 | G24: 73448 | H24: =BS!H13 -> 300 | I24: =BS!I13 -> 300
B25: Total Equity | C25: 138245 | D25: 146043 | E25: 201875 | F25: 285970 | G25: 411065 | H25: =BS!H19 -> 20393 | I25: =BS!I19 -> 20393
B26: Net Debt | C26: 137651 | D26: 99900 | E26: 88040 | F26: 76772 | G26: 91282 | H26: =BS!H13-BS!H4 -> 300 | I26: =BS!I13-BS!I4 -> 300
